Workbook

Sheet Segmentación CENTRO
M1: Zona | N1: =VLOOKUP(N2,#REF!,4,0) -> #REF! | O1: =VLOOKUP(O2,#REF!,4,0) -> #REF! | P1: =VLOOKUP(P2,#REF!,4,0) -> #REF! | Q1: =VLOOKUP(Q2,#REF!,4,0) -> #REF! | R1: =VLOOKUP(R2,#REF!,4,0) -> #REF! | S1: =VLOOKUP(S2,#REF!,4,0) -> #REF! | T1: =VLOOKUP(T2,#REF!,4,0) -> #REF! | U1: =VLOOKUP(U2,#REF!,4,0) -> #REF! | ... DD1: =VLOOKUP(DD2,#REF!,4,0) -> #REF!
B2: PORTAFOLIO | C2: TIENDAS | D2: ITEMS | M2: Tienda | N2: S03 | O2: S11 | P2: S15 | Q2: S24 | R2: S25 | S2: S31 | T2: S32 | U2: S57 | V2: S60 | W2: S70 | X2: S72 | Y2: S90 | Z2: S97 | AA2: SA4 | AB2: SA6 | AC2: SA7 | AD2: SA9 | AE2: SB2 | AF2: SB3 | AG2: SB5 | AH2: SC0 | AI2: SC1 | AJ2: SC2 | AK2: SC8 | AL2: SD3 | AM2: SD4 | AN2: SD8 | AO2: SD9 | AP2: SE1 | AQ2: SE3 | AR2: S04 | AS2: S17 | AT2: S18 | AU2: S26 | AV2: S27 | AW2: S29 | AX2: S34 | AY2: S59 | AZ2: S65 | BA2: S74 | BB2: S78 | BC2: S79 | BD2: S80 | BE2: S82 | BF2: S83 | BG2: S93 | BH2: S94 | BI2: S98 | BJ2: SA0 | BK2: SA1 | BL2: SA5 | BM2: SB4 | BN2: SB7 | BO2: SB8 | BP2: SC4 | BQ2: SC5 | BR2: SD0 | BS2: SD5 | BT2: SE5 | BU2: SE6 | BV2: SE8 | BW2: S06 | BX2: S07 | BY2: S09 | BZ2: S16 | CA2: S19 | CB2: S20 | CC2: S30 | CD2: S53 | CE2: S55 | CF2: S56 | CG2: S63 | CH2: S69 | CI2: S71 | CJ2: S86 | CK2: S73 | CL2: S87 | CM2: S96 | CN2: SA8 | CO2: SB0 | CP2: SB1 | CQ2: SB6 | CR2: SB9 | CS2: SC3 | CT2: SA2 | CU2: SC6 | CV2: SC7 | CW2: SD1 | CX2: SD6 | CY2: SD7 | CZ2: SE0 | DA2: SE2 | DB2: SE4 | DC2: SE7 | DD2: SC9
B3: BASICO | C3: 30 | D3: 22 | M3: Nombre tienda | N3: SUBA VILLA GLORIA | O3: UBATE JJ | P3: FONTIBON PLAZA | Q3: JUAN REY | R3: LA VICTORIA | S3: CHIPAQUE CENTRO | T3: SOACHA DESPENSA | U3: BOSA LAURELES | V3: LUCERO BAJO | W3: SILVANIA | X3: PATIO BONITO 87 | Y3: SAN JOAQUIN B | Z3: SAN VICENTE FERRER | AA3: ISIMO LOMAS | AB3: ISIMO VARIANTE CELTA | AC3: ISIMO TIBABUYES | AD3: ISIMO INDEPENDENCIA | AE3: ISIMO ESMERALDA | AF3: ISIMO LA ESTACION | AG3: ISIMO BOSA LA LIBERTAD | AH3: ISIMO DIVINO NIÑO | AI3: ISIMO DINDALITO | AJ3: VILLA SUAITA | AK3: MARCO FIDEL | AL3: TINTALITO | AM3: ISIMO LIBERTADORES | AN3: COSTA AZUL | AO3: SUBA LA GAITANA | AP3: RESTREPO OCCIDENTAL | AQ3: ISIMO SANTA LIBRADA | AR3: BOGOTA SUBA AURES 1 | AS3: FACA SANTANDER | AT3: FUNZA ZUAME | AU3: OLARTE VILLA DEL RIO | AV3: PARQUE LUIS CARLOS GALAN | AW3: SAN CRISTOBAL SUR | AX3: FUSAGASUGA | AY3: RESTREPO | AZ3: TABIO | BA3: CARMEN | BB3: CIUDAD JARDIN | BC3: USME PUEBLO | BD3: ZIPAQUIRA LA PAZ | BE3: SOACHA ESQUINA | BF3: MONTE BLANCO | BG3: SOPO CENTRO | BH3: MINUTO DE DIOS | BI3: VILLA GLADY | BJ3: SAN FRANCISCO | BK3: SAN BLAS | BL3: ISIMO EL TREBOL | BM3: ISIMO SANTAFE | BN3: ISIMO LIJACA | BO3: ISIMO MONTANA | BP3: BRAVO PAEZ | BQ3: TIHUAQUE | BR3: VILLA ESPERANZA | BS3: VILLA SONIA | BT3: ISIMO MOLINOS | BU3: ISIMO LUCERO SUR | BV3: ISIMO FUSAGASUGA BALMORAL | BW3: CEDRO GOLF | BX3: LOS CEDROS | BY3: SANTA TERESA | BZ3: NORMANDIA OCCIDENTAL 2 | CA3: POLO CLUB | CB3: QUESADA | CC3: SANTA RITA | CD3: QUINTA PAREDES EMBAJADA | CE3: QUIRIGUA | CF3: 22 SUR | CG3: SUBA HOSPITAL | CH3: MAZUREN | CI3: UNIR TIERRA NEGRA | CJ3: CHUCUA | CK3: NUEVO MUZÚ | CL3: RESERVAS DEL PORVENIR | CM3: MODELIA | CN3: ISIMO PRADO 138 | CO3: ISIMO TOSCANA | CP3: ISIMO ANILLO VIAL | CQ3: ISIMO CHIA CALATRAVA | CR3: ISIMO EL CAMPIN | CS3: UNICENTRO DE OCCIDENTE | CT3: SUBA FONTANAR | CU3: MANDALAY | CV3: LUJAN | CW3: CARIMAGUA | CX3: MILENIUM | CY3: CIUDAD ORIENTAL | CZ3: ISIMO MALL SANTA CRUZ | DA3: ISIMO VILLA ALSACIA | DB3: ISIMO LEON XIII | DC3: ISIMO SUBA CRA 91 | DD3: BOSA NARANJO
M4: N S E | N4: MED ALTO | O4: MED ALTO | P4: BAJO | Q4: BAJO | R4: BAJO | S4: BAJO | T4: MED ALTO | U4: BAJO | V4: BAJO | W4: BAJO | X4: BAJO | Y4: BAJO | Z4: MED ALTO | AA4: BAJO | AB4: MED ALTO | AC4: MED ALTO | AD4: BAJO | AE4: MED ALTO | AF4: MED ALTO | AG4: BAJO | AH4: MED ALTO | AI4: BAJO | AJ4: BAJO | AK4: BAJO | AL4: BAJO | AM4: BAJO | AN4: MED ALTO | AO4: BAJO | AP4: MED ALTO | AQ4: BAJO | AR4: BAJO | AS4: MED ALTO | AT4: MED ALTO | AU4: BAJO | AV4: MED ALTO | AW4: BAJO | AX4: MED ALTO | AY4: MED ALTO | AZ4: MED ALTO | BA4: BAJO | BB4: MED ALTO | BC4: BAJO | BD4: MED ALTO | BE4: MED ALTO | BF4: BAJO | BG4: MED ALTO | BH4: MED ALTO | BI4: MED ALTO | BJ4: BAJO | BK4: MED ALTO | BL4: MED ALTO | BM4: BAJO | BN4: MED ALTO | BO4: MED ALTO | BP4: MED ALTO | BQ4: BAJO | BR4: BAJO | BS4: BAJO | BT4: BAJO | BU4: BAJO | BV4: MED ALTO | BW4: MED ALTO | BX4: MED ALTO | BY4: MED ALTO | BZ4: MED ALTO | CA4: MED ALTO | CB4: MED ALTO | CC4: BAJO | CD4: MED ALTO | CE4: MED ALTO | CF4: MED ALTO | CG4: MED ALTO | CH4: MED ALTO | CI4: MED ALTO | CJ4: MED ALTO | CK4: BAJO | CL4: BAJO | CM4: MED ALTO | CN4: MED ALTO | CO4: MED ALTO | CP4: MED ALTO | CQ4: MED ALTO | CR4: MED ALTO | CS4: MED ALTO | CT4: MED ALTO | CU4: MED ALTO | CV4: MED ALTO | CW4: MED ALTO | CX4: MED ALTO | CY4: MED ALTO | CZ4: BAJO | DA4: MED ALTO | DB4: BAJO | DC4: BAJO | DD4: BAJO
B5: EXTENDIDO | C5: 31 | D5: 19 | M5: NEVERA AUTOCONTENIDA | CA5: NO
B6: NEVERA F | C6: 33 | D6: 20 | M6: CANTIDAD MUEBLES FRUVER
B7: EXCEPCIÓN | C7: 1 | M7: VTA PROM FRUVER
M8: TIPO DE PORTAFOLIO | N8: B | O8: B | P8: B | Q8: B | R8: B | S8: B | T8: B | U8: B | V8: B | W8: B | X8: B | Y8: B | Z8: B | AA8: B | AB8: B | AC8: B | AD8: B | AE8: B | AF8: B | AG8: B | AH8: B | AI8: B | AJ8: B | AK8: B | AL8: B | AM8: B | AN8: B | AO8: B | AP8: B | AQ8: B | AR8: B + E | AS8: B + E | AT8: B + E | AU8: B + E | AV8: B + E | AW8: B + E | AX8: B + E | AY8: B + E | AZ8: B + E | BA8: B + E | BB8: B + E | BC8: B + E | BD8: B + E | BE8: B + E | BF8: B + E | BG8: B + E | BH8: B + E | BI8: B + E | BJ8: B + E | BK8: B + E | BL8: B + E | BM8: B + E | BN8: B + E | BO8: B + E | BP8: B + E | BQ8: B + E | BR8: B + E | BS8: B + E | BT8: B + E | BU8: B + E | BV8: B + E | BW8: B + E +N | BX8: B + E +N | BY8: B + E +N | BZ8: B + E +N | CA8: B + E +N | CB8: B + E +N | CC8: B + E +N | CD8: B + E +N | CE8: B + E +N | CF8: B + E +N | CG8: B + E +N | CH8: B + E +N | CI8: B + E +N | CJ8: B + E +N | CK8: B + E +N | CL8: B + E +N | CM8: B + E +N | CN8: B + E +N | CO8: B + E +N | CP8: B + E +N | CQ8: B + E +N | CR8: B + E +N | CS8: B + E +N | CT8: B + E +N | CU8: B + E +N | CV8: B + E +N | CW8: B + E +N | CX8: B + E +N | CY8: B + E +N | CZ8: B + E +N | DA8: B + E +N | DB8: B + E +N | DC8: B + E +N | DD8: excepción
A9: ITEM | B9: DESCRIPCION | C9: CLUSTERIZACIÓN | D9: CLUSTERIZACIÓN | E9: ESTADO | F9: $ MERMA | G9: % MERMA | H9: VENTA | I9: EXHIBICION | J9: CARAS BSC | K9: CARAS BSC+EXT | L9: CARAS BSC+EXT+NEV | M9: U.M. | N9: 22 | O9: 22 | P9: 22 | Q9: 22 | R9: 22 | S9: 22 | T9: 22 | U9: 22 | V9: 22 | W9: 22 | X9: 22 | Y9: 22 | Z9: 22 | AA9: 22 | AB9: 22 | AC9: 22 | AD9: 22 | AE9: 22 | AF9: 22 | AG9: 22 | AH9: 22 | AI9: 22 | AJ9: 22 | AK9: 22 | AL9: 22 | AM9: 22 | AN9: 22 | AO9: 22 | AP9: 22 | AQ9: 22 | AR9: 41 | AS9: 41 | AT9: 41 | AU9: 41 | AV9: 41 | AW9: 41 | AX9: 41 | AY9: 41 | AZ9: 41 | BA9: 41 | BB9: 41 | BC9: 41 | BD9: 41 | BE9: 41 | BF9: 41 | BG9: 41 | BH9: 41 | BI9: 41 | BJ9: 41 | BK9: 41 | BL9: 41 | BM9: 41 | BN9: 41 | BO9: 41 | BP9: 41 | BQ9: 41 | BR9: 41 | BS9: 41 | BT9: 41 | BU9: 41 | BV9: 41 | BW9: 61 | BX9: 61 | BY9: 61 | BZ9: 61 | CA9: 61 | CB9: 61 | CC9: 61 | CD9: 61 | CE9: 61 | CF9: 61 | CG9: 61 | CH9: 61 | CI9: 61 | CJ9: 61 | CK9: 61 | CL9: 61 | CM9: 41 | CN9: 61 | CO9: 61 | CP9: 61 | CQ9: 61 | CR9: 61 | CS9: 61 | CT9: 61 | CU9: 61 | CV9: 61 | CW9: 61 | CX9: 61 | CY9: 61 | CZ9: 61 | DA9: 61 | DB9: 61 | DC9: 61 | DD9: 13
A10: 1561 | B10: AGUACATE HASS UND | C10: BASICO | D10: TODOS | E10: ACTIVO | I10: SECO | J10: 1 | K10: 1 | L10: 1 | M10: CN36 | N10: X | O10: X | P10: X | Q10: X | R10: X | S10: X | T10: X | U10: X | V10: X | W10: X | X10: X | Y10: X | Z10: X | AA10: X | AB10: X | AC10: X | AD10: X | AE10: X | AF10: X | AG10: X | AH10: X | AI10: X | AJ10: X | AK10: X | AL10: X | AM10: X | AN10: X | AO10: X | AP10: X | AQ10: X | AR10: X | AS10: X | AT10: X | AU10: X | AV10: X | AW10: X | AX10: X | AY10: X | AZ10: X | BA10: X | BB10: X | BC10: X | BD10: X | BE10: X | BF10: X | BG10: X | BH10: X | BI10: X | BJ10: X | BK10: X | BL10: X | BM10: X | BN10: X | BO10: X | BP10: X | BQ10: X | BR10: X | BS10: X | BT10: X | BU10: X | BV10: X | BW10: X | BX10: X | BY10: X | BZ10: X | CA10: X | CB10: X | CC10: X | CD10: X | CE10: X | CF10: X | CG10: X | CH10: X | CI10: X | CJ10: X | CK10: X | CL10: X | CM10: X | CN10: X | CO10: X | CP10: X | CQ10: X | CR10: X | CS10: X | CT10: X | CU10: X | CV10: X | CW10: X | CX10: X | CY10: X | CZ10: X | DA10: X | DB10: X | DC10: X
A11: 1074 | B11: AGUACATE VARIEDAD UNIDAD | C11: BASICO | D11: MEDIO ALTO | E11: ACTIVO | I11: SECO | K11: 1 | L11: 1 | M11: CN10 | N11: X | O11: X | T11: X | Z11: X | AB11: X | AC11: X | AE11: X | AF11: X | AH11: X | AN11: X | AP11: X | AS11: X | AT11: X | AV11: X | AX11: X | AY11: X | AZ11: X | BB11: X | BD11: X | BE11: X | BG11: X | BH11: X | BI11: X | BK11: X | BL11: X | BN11: X | BO11: X | BP11: X | BV11: X | BW11: X | BX11: X | BY11: X | BZ11: X | CA11: X | CB11: X | CD11: X | CE11: X | CF11: X | CG11: X | CH11: X | CI11: X | CJ11: X | CM11: X | CN11: X | CO11: X | CP11: X | CQ11: X | CR11: X | CS11: X | CT11: X | CU11: X | CV11: X | CW11: X | CX11: X | CY11: X | DA11: X
A12: 1819 | B12: AHUYAMA ZAKATA 600 G | C12: EXTENDIDO | D12: TODOS | E12: ACTIVO | I12: SECO | L12: 1 | M12: CN10 | AR12: X | AS12: X | AT12: X | AU12: X | AV12: X | AW12: X | AX12: X | AY12: X | AZ12: X | BA12: X | BB12: X | BC12: X | BD12: X | BE12: X | BF12: X | BG12: X | BH12: X | BI12: X | BJ12: X | BK12: X | BL12: X | BM12: X | BN12: X | BO12: X | BP12: X | BQ12: X | BR12: X | BS12: X | BT12: X | BU12: X | BV12: X | BW12: X | BX12: X | BY12: X | BZ12: X | CA12: X | CB12: X | CC12: X | CD12: X | CE12: X | CF12: X | CG12: X | CH12: X | CI12: X | CJ12: X | CK12: X | CL12: X | CM12: X | CN12: X | CO12: X | CP12: X | CQ12: X | CR12: X | CS12: X | CT12: X | CU12: X | CV12: X | CW12: X | CX12: X | CY12: X | CZ12: X | DA12: X | DB12: X | DC12: X
A13: 155 | B13: AJO 3 UND | C13: BASICO | D13: TODOS | E13: ACTIVO | I13: SECO | J13: 1 | K13: 1 | L13: 1 | M13: CN50 | N13: X | O13: X | P13: X | Q13: X | R13: X | S13: X | T13: X | U13: X | V13: X | W13: X | X13: X | Y13: X | Z13: X | AA13: X | AB13: X | AC13: X | AD13: X | AE13: X | AF13: X | AG13: X | AH13: X | AI13: X | AJ13: X | AK13: X | AL13: X | AM13: X | AN13: X | AO13: X | AP13: X | AQ13: X | AR13: X | AS13: X | AT13: X | AU13: X | AV13: X | AW13: X | AX13: X | AY13: X | AZ13: X | BA13: X | BB13: X | BC13: X | BD13: X | BE13: X | BF13: X | BG13: X | BH13: X | BI13: X | BJ13: X | BK13: X | BL13: X | BM13: X | BN13: X | BO13: X | BP13: X | BQ13: X | BR13: X | BS13: X | BT13: X | BU13: X | BV13: X | BW13: X | BX13: X | BY13: X | BZ13: X | CA13: X | CB13: X | CC13: X | CD13: X | CE13: X | CF13: X | CG13: X | CH13: X | CI13: X | CJ13: X | CK13: X | CL13: X | CM13: X | CN13: X | CO13: X | CP13: X | CQ13: X | CR13: X | CS13: X | CT13: X | CU13: X | CV13: X | CW13: X | CX13: X | CY13: X | CZ13: X | DA13: X | DB13: X | DC13: X | DD13: X
A14: 1793 | B14: APIO 300 G | C14: NEVERA F | D14: TODOS | E14: INACTIVO | I14: FRIO | L14: 1 | M14: CN08 | BW14: X | BX14: X | BY14: X | BZ14: X | CA14: X | CB14: X | CC14: X | CD14: X | CE14: X | CF14: X | CG14: X | CH14: X | CI14: X | CK14: X | CL14: X | CN14: X | CP14: X | CQ14: X | CR14: X | CS14: X | CU14: X | CV14: X | CW14: X | CX14: X | CY14: X | CZ14: X | DA14: X | DB14: X | DC14: X
A15: 157 | B15: ARANDANOS FRESCOS 125 G | C15: BASICO | D15: TODOS | E15: ACTIVO | I15: FRIO | J15: 1 | K15: 1 | L15: 1 | M15: CN12 | N15: X | O15: X | P15: X | Q15: X | R15: X | S15: X | T15: X | U15: X | V15: X | W15: X | X15: X | Y15: X | Z15: X | AA15: X | AB15: X | AC15: X | AD15: X | AE15: X | AF15: X | AG15: X | AH15: X | AI15: X | AJ15: X | AK15: X | AL15: X | AM15: X | AN15: X | AO15: X | AP15: X | AQ15: X | AR15: X | AS15: X | AT15: X | AU15: X | AV15: X | AW15: X | AX15: X | AY15: X | AZ15: X | BA15: X | BB15: X | BC15: X | BD15: X | BE15: X | BF15: X | BG15: X | BH15: X | BI15: X | BJ15: X | BK15: X | BL15: X | BM15: X | BN15: X | BO15: X | BP15: X | BQ15: X | BR15: X | BS15: X | BT15: X | BU15: X | BV15: X | BW15: X | BX15: X | BY15: X | BZ15: X | CA15: X | CB15: X | CC15: X | CD15: X | CE15: X | CF15: X | CG15: X | CH15: X | CI15: X | CJ15: X | CK15: X | CL15: X | CM15: X | CN15: X | CO15: X | CP15: X | CQ15: X | CR15: X | CS15: X | CT15: X | CU15: X | CV15: X | CW15: X | CX15: X | CY15: X | CZ15: X | DA15: X | DB15: X | DC15: X | DD15: X
A16: 2602 | B16: ARANDANOS FRESCOS PURE VALLEY 125 G | C16: BASICO | D16: TODOS | E16: ACTIVO | I16: FRIO | N16: X | O16: X | P16: X | Q16: X | R16: X | S16: X | T16: X | U16: X | V16: X | W16: X | X16: X | Y16: X | Z16: X | AA16: X | AB16: X | AC16: X | AD16: X | AE16: X | AF16: X | AG16: X | AH16: X | AI16: X | AJ16: X | AK16: X | AL16: X | AM16: X | AN16: X | AO16: X | AP16: X | AQ16: X | AR16: X | AS16: X | AT16: X | AU16: X | AV16: X | AW16: X | AX16: X | AY16: X | AZ16: X | BA16: X | BB16: X | BC16: X | BD16: X | BE16: X | BF16: X | BG16: X | BH16: X | BI16: X | BJ16: X | BK16: X | BL16: X | BM16: X | BN16: X | BO16: X | BP16: X | BQ16: X | BR16: X | BS16: X | BT16: X | BU16: X | BV16: X | BW16: X | BX16: X | BY16: X | BZ16: X | CA16: X | CB16: X | CC16: X | CD16: X | CE16: X | CF16: X | CG16: X | CH16: X | CI16: X | CJ16: X | CK16: X | CL16: X | CM16: X | CN16: X | CO16: X | CP16: X | CQ16: X | CR16: X | CS16: X | CT16: X | CU16: X | CV16: X | CW16: X | CX16: X | CY16: X | CZ16: X | DA16: X | DB16: X | DC16: X
A17: 3103 | B17: ARANDANOS FRESCOS 500 G | C17: EXTENDIDO | D17: TODOS | E17: ACTIVO | I17: FRIO | AR17: X | AS17: X | AT17: X | AU17: X | AV17: X | AW17: X | AX17: X | AY17: X | AZ17: X | BA17: X | BB17: X | BC17: X | BD17: X | BE17: X | BF17: X | BG17: X | BH17: X | BI17: X | BJ17: X | BK17: X | BL17: X | BM17: X | BN17: X | BO17: X | BP17: X | BQ17: X | BR17: X | BS17: X | BT17: X | BU17: X | BV17: X | BW17: X | BX17: X | BY17: X | BZ17: X | CA17: X | CB17: X | CC17: X | CD17: X | CE17: X | CF17: X | CG17: X | CH17: X | CI17: X | CJ17: X | CK17: X | CL17: X | CM17: X | CN17: X | CO17: X | CP17: X | CQ17: X | CR17: X | CS17: X | CT17: X | CU17: X | CV17: X | CW17: X | CX17: X | CY17: X | CZ17: X | DA17: X | DB17: X | DC17: X
A18: 1794 | B18: ARVEJA DESGRANADA 150 G | C18: NEVERA F | D18: MEDIO ALTO | E18: ACTIVO | I18: FRIO | BW18: X | BX18: X | BY18: X | BZ18: X | CA18: X | CB18: X | CD18: X | CE18: X | CF18: X | CG18: X | CH18: X | CI18: X | CJ18: X | CN18: X | CO18: X | CP18: X | CQ18: X | CR18: X | CS18: X | CT18: X | CU18: X | CV18: X | CW18: X | CX18: X | CY18: X | DA18: X
A19: 1210 | B19: BANANO UNIDAD | C19: BASICO | D19: TODOS | E19: ACTIVO | I19: SECO | J19: 1 | K19: 1 | L19: 1 | M19: C100 | N19: X | O19: X | P19: X | Q19: X | R19: X | S19: X | T19: X | U19: X | V19: X | W19: X | X19: X | Y19: X | Z19: X | AA19: X | AB19: X | AC19: X | AD19: X | AE19: X | AF19: X | AG19: X | AH19: X | AI19: X | AJ19: X | AK19: X | AL19: X | AM19: X | AN19: X | AO19: X | AP19: X | AQ19: X | AR19: X | AS19: X | AT19: X | AU19: X | AV19: X | AW19: X | AX19: X | AY19: X | AZ19: X | BA19: X | BB19: X | BC19: X | BD19: X | BE19: X | BF19: X | BG19: X | BH19: X | BI19: X | BJ19: X | BK19: X | BL19: X | BM19: X | BN19: X | BO19: X | BP19: X | BQ19: X | BR19: X | BS19: X | BT19: X | BU19: X | BV19: X | BW19: X | BX19: X | BY19: X | BZ19: X | CA19: X | CB19: X | CC19: X | CD19: X | CE19: X | CF19: X | CG19: X | CH19: X | CI19: X | CJ19: X | CK19: X | CL19: X | CM19: X | CN19: X | CO19: X | CP19: X | CQ19: X | CR19: X | CS19: X | CT19: X | CU19: X | CV19: X | CW19: X | CX19: X | CY19: X | CZ19: X | DA19: X | DB19: X | DC19: X | DD19: X
A20: 1795 | B20: BROCOLI 250 G | C20: NEVERA F | D20: TODOS | E20: ACTIVO | I20: FRIO | L20: 1 | M20: CN06 | BW20: X | BX20: X | BY20: X | BZ20: X | CA20: X | CB20: X | CC20: X | CD20: X | CE20: X | CF20: X | CG20: X | CH20: X | CI20: X | CJ20: X | CK20: X | CL20: X | CN20: X | CO20: X | CP20: X | CQ20: X | CR20: X | CS20: X | CT20: X | CU20: X | CV20: X | CW20: X | CX20: X | CY20: X | CZ20: X | DA20: X | DB20: X | DC20: X
A21: 2472 | B21: CEBOLLA BLANCA SEMIPELADA CABEZONA 1000 G | C21: BASICO | D21: TODOS | E21: INACTIVO | I21: SECO | J21: 1 | K21: 1 | L21: 1 | M21: CN10 | N21: X | O21: X | P21: X | Q21: X | R21: X | S21: X | T21: X | U21: X | V21: X | W21: X | X21: X | Y21: X | Z21: X | AA21: X | AB21: X | AC21: X | AD21: X | AE21: X | AF21: X | AG21: X | AH21: X | AI21: X | AJ21: X | AK21: X | AL21: X | AM21: X | AN21: X | AO21: X | AP21: X | AQ21: X | AR21: X | AS21: X | AT21: X | AU21: X | AV21: X | AW21: X | AX21: X | AY21: X | AZ21: X | BA21: X | BB21: X | BC21: X | BD21: X | BE21: X | BF21: X | BG21: X | BH21: X | BI21: X | BJ21: X | BK21: X | BL21: X | BM21: X | BN21: X | BO21: X | BP21: X | BQ21: X | BR21: X | BS21: X | BT21: X | BU21: X | BV21: X | BW21: X | BX21: X | BY21: X | BZ21: X | CA21: X | CB21: X | CC21: X | CD21: X | CE21: X | CF21: X | CG21: X | CH21: X | CI21: X | CJ21: X | CK21: X | CL21: X | CM21: X | CN21: X | CO21: X | CP21: X | CQ21: X | CR21: X | CS21: X | CT21: X | CU21: X | CV21: X | CW21: X | CX21: X | CY21: X | CZ21: X | DA21: X | DB21: X | DC21: X
A22: 175 | B22: CEBOLLA BLANCA CABEZONA 500 G | C22: BASICO | D22: TODOS | E22: ACTIVO | I22: SECO | J22: 1 | K22: 1 | L22: 1 | M22: CN12 | N22: X | O22: X | P22: X | Q22: X | R22: X | S22: X | T22: X | U22: X | V22: X | W22: X | X22: X | Y22: X | Z22: X | AA22: X | AB22: X | AC22: X | AD22: X | AE22: X | AF22: X | AG22: X | AH22: X | AI22: X | AJ22: X | AK22: X | AL22: X | AM22: X | AN22: X | AO22: X | AP22: X | AQ22: X | AR22: X | AS22: X | AT22: X | AU22: X | AV22: X | AW22: X | AX22: X | AY22: X | AZ22: X | BA22: X | BB22: X | BC22: X | BD22: X | BE22: X | BF22: X | BG22: X | BH22: X | BI22: X | BJ22: X | BK22: X | BL22: X | BM22: X | BN22: X | BO22: X | BP22: X | BQ22: X | BR22: X | BS22: X | BT22: X | BU22: X | BV22: X | BW22: X | BX22: X | BY22: X | BZ22: X | CA22: X | CB22: X | CC22: X | CD22: X | CE22: X | CF22: X | CG22: X | CH22: X | CI22: X | CJ22: X | CK22: X | CL22: X | CM22: X | CN22: X | CO22: X | CP22: X | CQ22: X | CR22: X | CS22: X | CT22: X | CU22: X | CV22: X | CW22: X | CX22: X | CY22: X | CZ22: X | DA22: X | DB22: X | DC22: X
A23: 2052 | B23: CEBOLLA LARGA 500G | C23: EXTENDIDO | D23: TODOS | E23: ACTIVO | I23: FRIO | K23: 1 | L23: 1 | M23: CN10 | AR23: X | AS23: X | AT23: X | AU23: X | AV23: X | AW23: X | AX23: X | AY23: X | AZ23: X | BA23: X | BB23: X | BC23: X | BD23: X | BE23: X | BF23: X | BG23: X | BH23: X | BI23: X | BJ23: X | BK23: X | BL23: X | BM23: X | BN23: X | BO23: X | BP23: X | BQ23: X | BR23: X | BS23: X | BT23: X | BU23: X | BV23: X | BW23: X | BX23: X | BY23: X | BZ23: X | CA23: X | CB23: X | CC23: X | CD23: X | CE23: X | CF23: X | CG23: X | CH23: X | CI23: X | CJ23: X | CK23: X | CL23: X | CM23: X | CN23: X | CO23: X | CP23: X | CQ23: X | CR23: X | CS23: X | CT23: X | CU23: X | CV23: X | CW23: X | CX23: X | CY23: X | CZ23: X | DA23: X | DB23: X | DC23: X
A24: 754 | B24: CEBOLLA ROJA 500 G | C24: EXTENDIDO | D24: TODOS | E24: ACTIVO | I24: SECO | K24: 1 | L24: 1 | M24: CN12 | AR24: X | AS24: X | AT24: X | AU24: X | AV24: X | AW24: X | AX24: X | AY24: X | AZ24: X | BA24: X | BB24: X | BC24: X | BD24: X | BE24: X | BF24: X | BG24: X | BH24: X | BI24: X | BJ24: X | BK24: X | BL24: X | BM24: X | BN24: X | BO24: X | BP24: X | BQ24: X | BR24: X | BS24: X | BT24: X | BU24: X | BV24: X | BW24: X | BX24: X | BY24: X | BZ24: X | CA24: X | CB24: X | CC24: X | CD24: X | CE24: X | CF24: X | CG24: X | CH24: X | CI24: X | CJ24: X | CK24: X | CL24: X | CM24: X | CN24: X | CO24: X | CP24: X | CQ24: X | CR24: X | CS24: X | CT24: X | CU24: X | CV24: X | CW24: X | CX24: X | CY24: X | CZ24: X | DA24: X | DB24: X | DC24: X
A25: 1815 | B25: CHAMPIÑON ENTERO 250 G | C25: NEVERA F | D25: TODOS | E25: ACTIVO | I25: FRIO | BW25: X | BX25: X | BY25: X | BZ25: X | CA25: X | CB25: X | CC25: X | CD25: X | CE25: X | CF25: X | CG25: X | CH25: X | CI25: X | CJ25: X | CK25: X | CL25: X | CN25: X | CO25: X | CP25: X | CQ25: X | CR25: X | CS25: X | CT25: X | CU25: X | CV25: X | CW25: X | CX25: X | CY25: X | CZ25: X | DA25: X | DB25: X | DC25: X
A26: 1796 | B26: CILANTRO 120 G | C26: NEVERA F | D26: TODOS | E26: INACTIVO | I26: FRIO | L26: 1 | M26: CN10 | BW26: X | BX26: X | BY26: X | BZ26: X | CA26: X | CB26: X | CC26: X | CD26: X | CE26: X | CF26: X | CG26: X | CH26: X | CI26: X | CK26: X | CL26: X | CN26: X | CP26: X | CQ26: X | CR26: X | CS26: X | CU26: X | CV26: X | CW26: X | CX26: X | CY26: X | CZ26: X | DA26: X | DB26: X | DC26: X
A27: 2606 | B27: CIRUELA IMPORTADA 500 G | C27: NEVERA F | D27: TODOS | E27: ACTIVO | I27: FRIO | L27: 1 | M27: CN12 | BW27: X | BX27: X | BY27: X | BZ27: X | CA27: X | CB27: X | CC27: X | CD27: X | CE27: X | CF27: X | CG27: X | CH27: X | CI27: X | CJ27: X | CK27: X | CL27: X | CN27: X | CO27: X | CP27: X | CQ27: X | CR27: X | CS27: X | CT27: X | CU27: X | CV27: X | CW27: X | CX27: X | CY27: X | CZ27: X | DA27: X | DB27: X | DC27: X
A28: 1797 | B28: CIRUELA NACIONAL 400 G | C28: NEVERA F | D28: TODOS | E28: ACTIVO | I28: FRIO | L28: 1 | M28: CN06 | BW28: X | BX28: X | BY28: X | BZ28: X | CA28: X | CB28: X | CC28: X | CD28: X | CE28: X | CF28: X | CG28: X | CH28: X | CI28: X | CJ28: X | CK28: X | CL28: X | CN28: X | CO28: X | CP28: X | CQ28: X | CR28: X | CS28: X | CT28: X | CU28: X | CV28: X | CW28: X | CX28: X | CY28: X | CZ28: X | DA28: X | DB28: X | DC28: X
A29: 1071 | B29: COGOLLO 3 UNIDADES 300 G | C29: NEVERA F | D29: MEDIO ALTO | E29: ACTIVO | I29: FRIO | L29: 1 | M29: CN10 | BW29: X | BX29: X | BY29: X | BZ29: X | CA29: X | CB29: X | CD29: X | CE29: X | CF29: X | CG29: X | CH29: X | CI29: X | CJ29: X | CN29: X | CO29: X | CP29: X | CQ29: X | CR29: X | CS29: X | CT29: X | CU29: X | CV29: X | CW29: X | CX29: X | CY29: X | DA29: X
A30: 1072 | B30: ESPINACA 150 G | C30: NEVERA F | D30: TODOS | E30: ACTIVO | I30: FRIO | L30: 1 | M30: CN10 | BW30: X | BX30: X | BY30: X | BZ30: X | CA30: X | CB30: X | CC30: X | CD30: X | CE30: X | CF30: X | CG30: X | CH30: X | CI30: X | CJ30: X | CK30: X | CL30: X | CN30: X | CO30: X | CP30: X | CQ30: X | CR30: X | CS30: X | CT30: X | CU30: X | CV30: X | CW30: X | CX30: X | CY30: X | CZ30: X | DA30: X | DB30: X | DC30: X
A31: 2603 | B31: FRESA 250 G - PURE VALLEY | C31: NEVERA F | D31: TODOS | E31: ACTIVO | I31: FRIO | K31: 1 | L31: 1 | M31: CN12 | BW31: X | BX31: X | BY31: X | BZ31: X | CA31: X | CB31: X | CC31: X | CD31: X | CE31: X | CF31: X | CG31: X | CH31: X | CI31: X | CJ31: X | CK31: X | CL31: X | CN31: X | CO31: X | CP31: X | CQ31: X | CR31: X | CS31: X | CT31: X | CU31: X | CV31: X | CW31: X | CX31: X | CY31: X | CZ31: X | DA31: X | DB31: X | DC31: X
A32: 3001 | B32: FRESA PARA JUGO 500 G | C32: EXTENDIDO | D32: TODOS | E32: ACTIVO | I32: FRIO | M32: CN10 | AR32: X | AS32: X | AT32: X | AU32: X | AV32: X | AW32: X | AX32: X | AY32: X | AZ32: X | BA32: X | BB32: X | BC32: X | BD32: X | BE32: X | BF32: X | BG32: X | BH32: X | BI32: X | BJ32: X | BK32: X | BL32: X | BM32: X | BN32: X | BO32: X | BP32: X | BQ32: X | BR32: X | BS32: X | BT32: X | BU32: X | BV32: X | BW32: X | BX32: X | BY32: X | BZ32: X | CA32: X | CB32: X | CC32: X | CD32: X | CE32: X | CF32: X | CG32: X | CH32: X | CI32: X | CJ32: X | CK32: X | CL32: X | CM32: X | CN32: X | CO32: X | CP32: X | CQ32: X | CR32: X | CS32: X | CT32: X | CU32: X | CV32: X | CW32: X | CX32: X | CY32: X | CZ32: X | DA32: X | DB32: X | DC32: X
A33: 3100 | B33: FLOR DE JAMAICA 15 G | C33: BASICO | D33: TODOS | E33: ACTIVO | I33: SECO | N33: X | O33: X | P33: X | Q33: X | R33: X | S33: X | T33: X | U33: X | V33: X | W33: X | X33: X | Y33: X | Z33: X | AA33: X | AB33: X | AC33: X | AD33: X | AE33: X | AF33: X | AG33: X | AH33: X | AI33: X | AJ33: X | AK33: X | AL33: X | AM33: X | AN33: X | AO33: X | AP33: X | AQ33: X | AR33: X | AS33: X | AT33: X | AU33: X | AV33: X | AW33: X | AX33: X | AY33: X | AZ33: X | BA33: X | BB33: X | BC33: X | BD33: X | BE33: X | BF33: X | BG33: X | BH33: X | BI33: X | BJ33: X | BK33: X | BL33: X | BM33: X | BN33: X | BO33: X | BP33: X | BQ33: X | BR33: X | BS33: X | BT33: X | BU33: X | BV33: X | BW33: X | BX33: X | BY33: X | BZ33: X | CA33: X | CB33: X | CC33: X | CD33: X | CE33: X | CF33: X | CG33: X | CH33: X | CI33: X | CJ33: X | CK33: X | CL33: X | CM33: X | CN33: X | CO33: X | CP33: X | CQ33: X | CR33: X | CS33: X | CT33: X | CU33: X | CV33: X | CW33: X | CX33: X | CY33: X | CZ33: X | DA33: X | DB33: X | DC33: X
A34: 1800 | B34: GRANADILLA 450 G | C34: EXTENDIDO | D34: TODOS | E34: ACTIVO | I34: SECO | K34: 1 | L34: 1 | M34: CN08 | AR34: X | AS34: X | AT34: X | AU34: X | AV34: X | AW34: X | AX34: X | AY34: X | AZ34: X | BA34: X | BB34: X | BC34: X | BD34: X | BE34: X | BF34: X | BG34: X | BH34: X | BI34: X | BJ34: X | BK34: X | BL34: X | BM34: X | BN34: X | BO34: X | BP34: X | BQ34: X | BR34: X | BS34: X | BT34: X | BU34: X | BV34: X | BW34: X | BX34: X | BY34: X | BZ34: X | CA34: X | CB34: X | CC34: X | CD34: X | CE34: X | CF34: X | CG34: X | CH34: X | CI34: X | CJ34: X | CK34: X | CL34: X | CM34: X | CN34: X | CO34: X | CP34: X | CQ34: X | CR34: X | CS34: X | CT34: X | CU34: X | CV34: X | CW34: X | CX34: X | CY34: X | CZ34: X | DA34: X | DB34: X | DC34: X
A35: 1801 | B35: GUAYABA PERA 500 G | C35: EXTENDIDO | D35: TODOS | E35: INACTIVO | I35: SECO | K35: 1 | L35: 1 | M35: CN08 | AR35: X | AS35: X | AT35: X | AU35: X | AV35: X | AW35: X | AX35: X | AY35: X | AZ35: X | BA35: X | BB35: X | BC35: X | BD35: X | BE35: X | BF35: X | BG35: X | BH35: X | BI35: X | BJ35: X | BK35: X | BL35: X | BM35: X | BN35: X | BO35: X | BP35: X | BQ35: X | BR35: X | BS35: X | BT35: X | BU35: X | BV35: X | BW35: X | BX35: X | BY35: X | BZ35: X | CA35: X | CB35: X | CC35: X | CD35: X | CE35: X | CF35: X | CG35: X | CH35: X | CI35: X | CJ35: X | CK35: X | CL35: X | CM35: X | CN35: X | CO35: X | CP35: X | CQ35: X | CR35: X | CS35: X | CT35: X | CU35: X | CV35: X | CW35: X | CX35: X | CY35: X | CZ35: X | DA35: X | DB35: X | DC35: X
A36: 1820 | B36: GULUPA 500 G | C36: EXTENDIDO | D36: TODOS | E36: INACTIVO | I36: SECO | K36: 1 | L36: 1 | M36: CN10 | AR36: X | AS36: X | AT36: X | AU36: X | AV36: X | AW36: X | AX36: X | AY36: X | AZ36: X | BA36: X | BB36: X | BC36: X | BD36: X | BE36: X | BF36: X | BG36: X | BH36: X | BI36: X | BJ36: X | BK36: X | BL36: X | BM36: X | BN36: X | BO36: X | BP36: X | BQ36: X | BR36: X | BS36: X | BT36: X | BU36: X | BV36: X | BW36: X | BX36: X | BY36: X | BZ36: X | CA36: X | CB36: X | CC36: X | CD36: X | CE36: X | CF36: X | CG36: X | CH36: X | CI36: X | CJ36: X | CK36: X | CL36: X | CM36: X | CN36: X | CO36: X | CP36: X | CQ36: X | CR36: X | CS36: X | CT36: X | CU36: X | CV36: X | CW36: X | CX36: X | CY36: X | CZ36: X | DA36: X | DB36: X | DC36: X
A37: 1803 | B37: KIWI 200 G | C37: EXTENDIDO | D37: TODOS | E37: ACTIVO | I37: FRIO | K37: 1 | L37: 1 | M37: CN08 | AR37: X | AS37: X | AT37: X | AU37: X | AV37: X | AW37: X | AX37: X | AY37: X | AZ37: X | BA37: X | BB37: X | BC37: X | BD37: X | BE37: X | BF37: X | BG37: X | BH37: X | BI37: X | BJ37: X | BK37: X | BL37: X | BM37: X | BN37: X | BO37: X | BP37: X | BQ37: X | BR37: X | BS37: X | BT37: X | BU37: X | BV37: X | BW37: X | BX37: X | BY37: X | BZ37: X | CA37: X | CB37: X | CC37: X | CD37: X | CE37: X | CF37: X | CG37: X | CH37: X | CI37: X | CJ37: X | CK37: X | CL37: X | CM37: X | CN37: X | CO37: X | CP37: X | CQ37: X | CR37: X | CS37: X | CT37: X | CU37: X | CV37: X | CW37: X | CX37: X | CY37: X | CZ37: X | DA37: X | DB37: X | DC37: X | DD37: X
A38: 3112 | B38: LECHUGA BATAVIA UND | C38: NEVERA F | D38: TODOS | E38: ACTIVO | I38: FRIO | BW38: X | BX38: X | BY38: X | BZ38: X | CA38: X | CB38: X | CC38: X | CD38: X | CE38: X | CF38: X | CG38: X | CH38: X | CI38: X | CJ38: X | CK38: X | CL38: X | CN38: X | CO38: X | CP38: X | CQ38: X | CR38: X | CS38: X | CT38: X | CU38: X | CV38: X | CW38: X | CX38: X | CY38: X | CZ38: X | DA38: X | DB38: X | DC38: X
A39: 1079 | B39: LECHUGA CRESPA VERDE UNIDAD | C39: NEVERA F | D39: TODOS | E39: ACTIVO | I39: FRIO | K39: 1 | L39: 1 | M39: CN12 | BW39: X | BX39: X | BY39: X | BZ39: X | CA39: X | CB39: X | CC39: X | CD39: X | CE39: X | CF39: X | CG39: X | CH39: X | CI39: X | CJ39: X | CK39: X | CL39: X | CN39: X | CO39: X | CP39: X | CQ39: X | CR39: X | CS39: X | CT39: X | CU39: X | CV39: X | CW39: X | CX39: X | CY39: X | CZ39: X | DA39: X | DB39: X | DC39: X
A40: 965 | B40: LIMON TAHITI 500 G | C40: BASICO | D40: TODOS | E40: INACTIVO | I40: SECO | J40: 1 | K40: 1 | L40: 1 | M40: CN12 | N40: X | O40: X | P40: X | Q40: X | R40: X | S40: X | T40: X | U40: X | V40: X | W40: X | X40: X | Y40: X | Z40: X | AA40: X | AB40: X | AC40: X | AD40: X | AE40: X | AF40: X | AG40: X | AH40: X | AI40: X | AJ40: X | AK40: X | AL40: X | AM40: X | AN40: X | AO40: X | AP40: X | AQ40: X | AR40: X | AS40: X | AT40: X | AU40: X | AV40: X | AW40: X | AX40: X | AY40: X | AZ40: X | BA40: X | BB40: X | BC40: X | BD40: X | BE40: X | BF40: X | BG40: X | BH40: X | BI40: X | BJ40: X | BK40: X | BL40: X | BM40: X | BN40: X | BO40: X | BP40: X | BQ40: X | BR40: X | BS40: X | BT40: X | BU40: X | BV40: X | BW40: X | BX40: X | BY40: X | BZ40: X | CA40: X | CB40: X | CC40: X | CD40: X | CE40: X | CF40: X | CG40: X | CH40: X | CI40: X | CJ40: X | CK40: X | CL40: X | CM40: X | CN40: X | CO40: X | CP40: X | CQ40: X | CR40: X | CS40: X | CT40: X | CU40: X | CV40: X | CW40: X | CX40: X | CY40: X | CZ40: X | DA40: X | DB40: X | DC40: X
...

Sheet Hoja 10
A1: COD | B1: TIENDA | C1: FECHA APERTURA | F1: Tienda | G1: Nombre tienda | H1: N S E | I1: TIPO DE PORTAFOLIO | L1: CODIGO | M1: TIENDAS
A2: I05 | B2: RIONEGRO ALTOS DE LAURELES | C2: 44981 | F2: S03 | G2: SUBA VILLA GLORIA | H2: 3 | I2: B | L2: S04 | M2: SUBA AURES
A3: I02 | B3: ENVIGADO PARQUE | C3: 45016 | F3: S04 | G3: BOGOTA SUBA AURES 1 | H3: 2 | I3: B | L3: S06 | M3: CEDRO GOLF
A4: I07 | B4: SAN ANTONIO DE PEREIRA | C4: 45002 | F4: S13 | G4: ENGATIVÁ PUEBLO 2 | H4: 3 | I4: B | L4: S07 | M4: LOS CEDROS
A5: I08 | B5: MEDELLIN CALAZANS | C5: 44981 | F5: S15 | G5: FONTIBON PLAZA | H5: 2 | I5: B | L5: S09 | M5: SANTA TERESA
A6: I10 | B6: BARBOSA PARQUE | C6: 44992 | F6: S24 | G6: JUAN REY | H6: 2 | I6: B | L6: S15 | M6: FONTIBON PLAZA
A7: I11 | B7: MEDELLIN NOGAL | C7: 45022 | F7: S25 | G7: LA VICTORIA | H7: 2 | I7: B | L7: S16 | M7: NORMANDIA OCCIDENTAL 2
A8: I12 | B8: BELLO GORETTI | C8: 45043 | F8: S31 | G8: CHIPAQUE CENTRO | H8: 2 | I8: B | L8: S17 | M8: FACA SANTANDER
A9: I14 | B9: MEDELLIN FLORIDA NUEVA | C9: 45043 | F9: S32 | G9: SOACHA DESPENSA | H9: 3 | I9: B | L9: S18 | M9: FUNZA ZUAME
A10: I18 | B10: MED SAN ANTONIO PRADO CASA DE LA CULTURA | C10: 45000 | F10: S34 | G10: FUSAGASUGA | H10: 3 | I10: B | L10: S20 | M10: QUESADA
A11: I21 | B11: ITAGUI TABLAZO | C11: 45077 | F11: S57 | G11: BOSA LAURELES | H11: 2 | I11: B | L11: S27 | M11: PARQUE LUIS CARLOS GALAN
A12: I27 | B12: MEDELLÍN BUENOS AIRES | C12: 44985 | F12: S60 | G12: LUCERO BAJO | H12: 2 | I12: B | L12: S29 | M12: SAN CRISTOBAL SUR
A13: I29 | B13: MEDELLIN PILARICA CALLE 75 | C13: 45017 | F13: S70 | G13: SILVANIA | H13: 2 | I13: B | L13: S30 | M13: SANTA RITA
... A28: Q52 | B28: BARRANQUILLA EL SILENCIO | C28: 45040 | F28: SC8 | G28: MARCO FIDEL | H28: 3 | I28: B | L28: S94 | M28: MINUTO DE DIOS
A29: Q64 | B29: ATLANTICO SOLEDAD 2000 CARRERA 14 | C29: 45054 | F29: SD3 | G29: TINTALITO | I29: B | L29: S96 | M29: MODELIA
A30: Q66 | B30: BARRANQUILLA SAN REMO | C30: 45045 | F30: SD5 | G30: VILLA SONIA | I30: B | L30: S98 | M30: VILLA GLADYS
A31: Q67 | B31: BARRANQUILLA SAN NICOLAS CARRERA 4 | C31: 44926 | F31: SD9 | G31: SUBA LA GAITANA | I31: B | L31: SA0 | M31: SAN FRANCISCO
A32: Q68 | B32: GALAPA CLLE 10 | C32: 45030 | F32: SE1 | G32: RESTREPO OCCIDENTAL | I32: B | L32: SA2 | M32: SUBA FONTANAR
A33: Q69 | B33: BARRANQUILLA OLAYA CALLE 71 | C33: 45030 | F33: SD0 | G33: VILLA ESPERANZA | H33: 2 | I33: B + E | L33: SA5 | M33: EL TREBOL
A34: Q71 | B34: BARRANQUILLA LAS DELICIAS | C34: 45021 | F34: SD4 | G34: ISIMO LIBERTADORES | H34: 2 | I34: B + E | L34: SA6 | M34: FUNZA VARIANTE CELTA
A35: Q01 | B35: ATLAN PUERTO COLOMBIA VILLA CAMPESTRE | C35: 44923 | F35: S08 | G35: SAN ANTONIO | H35: 3 | I35: B + E | L35: SA7 | M35: TIBABUYES
A36: Q04 | B36: CARTAGENA LAS RAMBLAS | C36: 45020 | F36: S17 | G36: FACA SANTANDER | H36: 3 | I36: B + E | L36: SA8 | M36: PRADO 138
A37: Q07 | B37: BARRANQUILLA CALLE 84 | C37: 44970 | F37: S18 | G37: FUNZA ZUAME | H37: 3 | I37: B + E | L37: SA9 | M37: INDEPENDENCIA
A38: Q08 | B38: CARTAGENA EL CABRERO | C38: 44960 | F38: S26 | G38: OLARTE VILLA DEL RIO | H38: 2 | I38: B + E | L38: SB0 | M38: TOSCANA
A39: Q13 | B39: CARTAGENA MATUNA | C39: 45059 | F39: S27 | G39: PARQUE LUIS CARLOS GALAN | H39: 3 | I39: B + E | L39: SB1 | M39: ANILLO VIAL
A40: Q19 | B40: BARRANQUILLA EL PORVENIR CALLE 82 | C40: 44918 | F40: S59 | G40: RESTREPO | H40: 3 | I40: B + E | L40: SB3 | M40: LA ESTACION
A41: Q23 | B41: BARRANQUILLA CONCEPCION | C41: 45014 | F41: S78 | G41: CIUDAD JARDIN | H41: 3 | I41: B + E | L41: SB4 | M41: SANTAFE
A42: Q34 | B42: SANTA MARTA BONDA | C42: 45015 | F42: S79 | G42: USME PUEBLO | H42: 2 | I42: B + E | L42: SB5 | M42: BOSA LA LIBERTAD
A43: Q35 | B43: CARTAGENA CRESPO | C43: 44985 | F43: S80 | G43: ZIPAQUIRA LA PAZ | H43: 3 | I43: B + E | L43: SB6 | M43: CALATRAVA
A44: Q37 | B44: BARRANQUILLA CARRERA 21 | C44: 45021 | F44: S86 | G44: CHUCUA | H44: 3 | I44: B + E | L44: SB8 | M44: ISIMO MONTANA
... A64: S94 | B64: MINUTO DE DIOS | C64: 45077 | F64: S09 | G64: SANTA TERESA | H64: 4 | I64: B + E +N | L64: SE8 | M64: FUSA BALMORA
A65: S15 | B65: FONTIBON PLAZA | C65: 44999 | F65: S16 | G65: NORMANDIA OCCIDENTAL 2 | H65: 4 | I65: B + E +N
A66: S59 | B66: RESTREPO | C66: 45091 | F66: S19 | G66: POLO CLUB | H66: 4 | I66: B + E +N
A67: S96 | B67: MODELIA | C67: 45163 | F67: S20 | G67: QUESADA | H67: 3 | I67: B + E +N
A68: S53 | B68: QUINTA PAREDES EMBAJADA | C68: 45083 | F68: S29 | G68: SAN CRISTOBAL SUR | H68: 2 | I68: B + E +N
A69: SB9 | B69: EL CAMPIN | C69: 45762 | F69: S30 | G69: SANTA RITA | H69: 2 | I69: B + E +N
A70: S16 | B70: NORMANDIA OCCIDENTAL 2 | C70: 44985 | F70: S53 | G70: QUINTA PAREDES EMBAJADA | H70: 4 | I70: B + E +N
A71: SC7 | B71: ISIMO LUJAN | C71: 45838 | F71: S55 | G71: QUIRIGUA | H71: 3 | I71: B + E +N
A72: S73 | B72: NUEVO MUZU | C72: 45128 | F72: S56 | G72: 22 SUR | H72: 3 | I72: B + E +N
A73: S74 | B73: CARMEN | C73: 45010 | F73: S63 | G73: SUBA HOSPITAL | H73: 3 | I73: B + E +N
...

Sheet Segmentación SUR - TOLIMA
L1: Tienda | M1: S01 | N1: T05 | O1: T06 | P1: T07 | Q1: T09 | R1: T11 | S1: T13 | T1: T16 | U1: T17 | V1: T19 | W1: T21 | X1: T23 | Y1: T27 | Z1: T29 | AA1: T30 | AB1: T31 | AC1: T33 | AD1: T34 | AE1: T36 | AF1: T37 | AG1: T39 | AH1: T40 | AI1: T41 | AJ1: T42 | AK1: T43 | AL1: T44 | AM1: T45 | AN1: T46 | AO1: T47 | AP1: T49 | AQ1: S02 | AR1: T14 | AS1: T20 | AT1: T25 | AU1: T50 | AV1: T02 | AW1: T15 | AX1: T48
L2: Nombre tienda | M2: GIRARDOT PANCHES | N2: MELGAR | O2: HONDA OBRERO | P2: SALADO 1 | Q2: CAJAMARCA | R2: LIBANO 1 | S2: FLANDES TOLIMA | T2: ORTEGA | U2: CHAPARRAL | V2: MARIQUITA 1 | W2: CARMEN DE APICALA | X2: CHAPARRAL 2 | Y2: EL CABRERO LA DORADA | Z2: ALVARADO | AA2: PLANADAS | AB2: TUNAL | AC2: IBAGUE LAS FERIAS | AD2: SANTA ISABEL | AE2: EL ESPINAL 4 Y GONGORA | AF2: INTERLAKEN | AG2: GUAMO 2 | AH2: VILLAHERMOSA | AI2: PRADO | AJ2: PALOCABILDO | AK2: FALAN | AL2: LA DORADA VILLA ESPERANZA | AM2: ATACO | AN2: PAYANDE | AO2: VILLA MARLEN | AP2: LA FRANCIA | AQ2: RICAURTE CUNDINAMARCA | AR2: PURIFICACION | AS2: MARIQUITA 2 | AT2: GAITAN IBAGUE | AU2: LEONES | AV2: IBAGUE LA POLA | AW2: IBAGUE LIMONAR | AX2: BELEN
L3: N S E | M3: 3 | N3: 2 | O3: 2 | P3: 2 | Q3: 2 | R3: 3 | S3: 2 | T3: 2 | U3: 2 | V3: 2 | W3: 2 | X3: 2 | Y3: 3 | Z3: 2 | AA3: 2 | AB3: 2 | AC3: 3 | AD3: 2 | AE3: 3 | AF3: 3 | AG3: 2 | AH3: 3 | AI3: 1 | AJ3: 2 | AK3: 3 | AL3: 2 | AM3: 2 | AN3: 2 | AO3: 3 | AP3: 3 | AQ3: 3 | AR3: 3 | AS3: 3 | AT3: 3 | AU3: 3 | AV3: 3 | AW3: 3 | AX3: 4
L4: NEVERA AUTOCONTENIDA | M4: NO | N4: NO | O4: NO | P4: NO | Q4: NO | R4: NO | S4: NO | T4: NO | U4: NO | V4: NO | W4: NO | X4: NO | Y4: NO | Z4: NO | AA4: NO | AB4: NO | AC4: NO | AD4: NO | AE4: NO | AF4: NO | AG4: NO | AH4: NO | AI4: NO | AJ4: NO | AK4: NO | AL4: NO | AM4: NO | AN4: NO | AO4: NO | AP4: NO | AQ4: NO | AR4: NO | AS4: NO | AT4: NO | AU4: NO | AV4: NO | AW4: NO | AX4: NO
L5: CANTIDAD MUEBLES FRUVER | M5: 2 | N5: 2 | O5: 2 | P5: 2 | Q5: 2 | R5: 2 | S5: 2 | T5: 2 | U5: 2 | V5: 2 | W5: 2 | X5: 1 | Y5: 1 | Z5: 2 | AA5: 2 | AB5: 1 | AC5: 2 | AD5: 2 | AE5: 2 | AF5: 1 | AG5: 2 | AH5: 1 | AI5: 1 | AJ5: 1 | AK5: 1 | AL5: 1 | AM5: 2 | AN5: 2 | AO5: 2 | AP5: 2 | AQ5: 2 | AR5: 2 | AS5: 2 | AT5: 2 | AU5: 2 | AV5: 2 | AW5: 2 | AX5: 2
L6: VTA PROM FRUVER | M6: 90296.333 | N6: 124927 | O6: 51647.667 | P6: 70541.333 | Q6: 103269.33 | R6: 39699.667 | S6: 106926 | T6: 63695 | U6: 44091.667 | V6: 92505 | W6: 88250.667 | X6: 80932.333 | Y6: 121646.67 | Z6: 113607.33 | AA6: 77033.667 | AB6: 106846.33 | AC6: 83808.333 | AD6: 92037 | AE6: 79659 | AF6: 79749 | AG6: 54773 | AH6: 51463.667 | AI6: 82851.667 | AJ6: 100680.67 | AK6: 67552 | AL6: 110469 | AM6: 110919.67 | AN6: 102363 | AO6: 167146 | AP6: 106468.67 | AQ6: 228063.67 | AR6: 43229 | AS6: 90127 | AT6: 125367.67 | AU6: 85998 | AV6: 308781 | AW6: 255657.33 | AX6: 270272.67
L7: % PARTICIP | M7: 0.017 | N7: 0.013 | O7: 0.011 | P7: 0.009 | Q7: 0.012 | R7: 0.008 | S7: 0.011 | T7: 0.008 | U7: 0.01 | V7: 0.018 | W7: 0.014 | X7: 0.012 | Y7: 0.022 | Z7: 0.013 | AA7: 0.011 | AB7: 0.015 | AC7: 0.008 | AD7: 0.016 | AE7: 0.012 | AF7: 0.013 | AG7: 0.01 | AH7: 0.006 | AI7: 0.01 | AJ7: 0.009 | AK7: 0.012 | AL7: 0.022 | AM7: 0.013 | AN7: 0.014 | AO7: 0.023 | AP7: 0.018 | AQ7: 0.02 | AR7: 0.019 | AS7: 0.018 | AT7: 0.024 | AU7: 0.021 | AV7: 0.036 | AW7: 0.047 | AX7: 0.029
L8: TIPO DE PORTAFOLIO | M8: B | N8: B | O8: B | P8: B | Q8: B | R8: B | S8: B | T8: B | U8: B | V8: B | W8: B | X8: B | Y8: B | Z8: B | AA8: B | AB8: B | AC8: B | AD8: B | AE8: B | AF8: B | AG8: B | AH8: B | AI8: B | AJ8: B | AK8: B | AL8: B | AM8: B | AN8: B | AO8: B | AP8: B | AQ8: B + E | AR8: B + E | AS8: B + E | AT8: B + E | AU8: B + E | AV8: B + E +N | AW8: B + E +N | AX8: B + E +N
A9: ITEM | B9: DESCRIPCION | C9: CLUSTERIZACIÓN | D9: ESTADO | E9: Merma 01 A 30 JUNIO $ | F9: % merma JUNIO | G9: venta JUNIO $ | H9: EXHIBICION | I9: CARAS BSC | J9: CARAS BSC+EXT | K9: CARAS BSC+EXT+NEV | L9: U.M. | M9: 18 | N9: 18 | O9: 18 | P9: 18 | Q9: 18 | R9: 18 | S9: 18 | T9: 18 | U9: 18 | V9: 18 | W9: 18 | X9: 18 | Y9: 18 | Z9: 18 | AA9: 18 | AB9: 18 | AC9: 18 | AD9: 18 | AE9: 18 | AF9: 18 | AG9: 18 | AH9: 18 | AI9: 18 | AJ9: 18 | AK9: 18 | AL9: 18 | AM9: 18 | AN9: 18 | AO9: 18 | AP9: 18 | AQ9: 31 | AR9: 31 | AS9: 31 | AT9: 31 | AU9: 31 | AV9: 42 | AW9: 42 | AX9: 42
A10: 1561 | B10: AGUACATE HASS UND | C10: BASICO | D10: ACTIVO | E10: 1074733.3 | F10: 0.21267866 | G10: 5053320 | H10: SECO | I10: 1 | J10: 1 | K10: 1 | L10: CN36 | M10: X | N10: X | O10: X | P10: X | Q10: X | R10: X | S10: X | T10: X | U10: X | V10: X | W10: X | X10: X | Y10: X | Z10: X | AA10: X | AB10: X | AC10: X | AD10: X | AE10: X | AF10: X | AG10: X | AH10: X | AI10: X | AJ10: X | AK10: X | AL10: X | AM10: X | AN10: X | AO10: X | AP10: X | AQ10: X | AR10: X | AS10: X | AT10: X | AU10: X | AV10: X | AW10: X | AX10: X
A11: 1074 | B11: AGUACATE VARIEDAD 400 G | C11: EXTENDIDO | D11: ACTIVO | E11: 264052.52 | F11: 0.16702354 | G11: 1580930 | H11: SECO | J11: 1 | K11: 1 | L11: CN10 | AQ11: X | AR11: X | AS11: X | AT11: X | AU11: X
A12: 1819 | B12: AHUYAMA ZAKATA 600 G | C12: EXTENDIDO | D12: ACTIVO | E12: 33929.72 | F12: 0.10273639 | G12: 330260 | H12: SECO | K12: 1 | L12: CN10 | AQ12: X | AR12: X | AS12: X | AT12: X | AU12: X
A13: 155 | B13: AJO 3 UND | C13: BASICO | D13: ACTIVO | E13: 161213.59 | F13: 0.026931233 | G13: 5986120 | H13: SECO | I13: 1 | J13: 1 | K13: 1 | L13: CN50 | M13: X | N13: X | O13: X | P13: X | Q13: X | R13: X | S13: X | T13: X | U13: X | V13: X | W13: X | X13: X | Y13: X | Z13: X | AA13: X | AB13: X | AC13: X | AD13: X | AE13: X | AF13: X | AG13: X | AH13: X | AI13: X | AJ13: X | AK13: X | AL13: X | AM13: X | AN13: X | AO13: X | AP13: X | AQ13: X | AR13: X | AS13: X | AT13: X | AU13: X | AV13: X | AW13: X | AX13: X
A14: 1793 | B14: APIO 300 G | C14: NEVERA F | D14: ACTIVO | E14: 50563.66 | F14: 0.17455608 | G14: 289670 | H14: FRIO | K14: 1 | L14: CN08 | AV14: X | AW14: X | AX14: X
A15: 157 | B15: ARANDANOS FRESCOS 125 G | C15: BASICO | D15: ACTIVO | E15: 490300.95 | F15: 0.054286493 | G15: 9031730 | H15: FRIO | I15: 1 | J15: 1 | K15: 1 | L15: CN12 | M15: X | N15: X | O15: X | P15: X | Q15: X | R15: X | S15: X | T15: X | U15: X | V15: X | W15: X | X15: X | Y15: X | Z15: X | AA15: X | AB15: X | AC15: X | AD15: X | AE15: X | AF15: X | AG15: X | AH15: X | AI15: X | AJ15: X | AK15: X | AL15: X | AM15: X | AN15: X | AO15: X | AP15: X | AQ15: X | AR15: X | AS15: X | AT15: X | AU15: X | AV15: X | AW15: X | AX15: X
A16: 1210 | B16: BANANO UNIDAD | C16: BASICO | D16: ACTIVO | E16: 2624081.2 | F16: 0.4169974 | G16: 6292800 | H16: SECO | I16: 1 | J16: 1 | K16: 1 | L16: C100 | M16: X | N16: X | O16: X | P16: X | Q16: X | R16: X | S16: X | T16: X | U16: X | V16: X | W16: X | X16: X | Y16: X | Z16: X | AA16: X | AB16: X | AC16: X | AD16: X | AE16: X | AF16: X | AG16: X | AH16: X | AI16: X | AJ16: X | AK16: X | AL16: X | AM16: X | AN16: X | AO16: X | AP16: X | AQ16: X | AR16: X | AS16: X | AT16: X | AU16: X | AV16: X | AW16: X | AX16: X
A17: 1795 | B17: BROCOLI 250 G | C17: NEVERA F | D17: ACTIVO | E17: 0 | F17: 0 | G17: 414960 | H17: FRIO | K17: 1 | L17: CN06 | AV17: X | AW17: X | AX17: X
A18: 2472 | B18: CEBOLLA BLANCA SEMIPELADA CABEZONA 1000 G | C18: BASICO | D18: INACTIVO | E18: #N/A | F18: #N/A | G18: #N/A | H18: SECO | I18: 1 | J18: 1 | K18: 1 | L18: CN10
A19: 175 | B19: CEBOLLA BLANCA CABEZONA 500 G | C19: BASICO | D19: ACTIVO | E19: 116093.7 | F19: 0.03319144 | G19: 3497700 | H19: SECO | I19: 1 | J19: 1 | K19: 1 | L19: CN12 | M19: X | N19: X | O19: X | P19: X | Q19: X | R19: X | S19: X | T19: X | U19: X | V19: X | W19: X | X19: X | Y19: X | Z19: X | AA19: X | AB19: X | AC19: X | AD19: X | AE19: X | AF19: X | AG19: X | AH19: X | AI19: X | AJ19: X | AK19: X | AL19: X | AM19: X | AN19: X | AO19: X | AP19: X | AQ19: X | AR19: X | AS19: X | AT19: X | AU19: X | AV19: X | AW19: X | AX19: X
A20: 2052 | B20: CEBOLLA LARGA 500G | C20: EXTENDIDO | D20: ACTIVO | E20: 82832.3 | F20: 0.10739867 | G20: 771260 | H20: FRIO | J20: 1 | K20: 1 | L20: CN10 | AQ20: X | AR20: X | AS20: X | AT20: X | AU20: X
A21: 754 | B21: CEBOLLA ROJA 500 G | C21: EXTENDIDO | D21: INACTIVO | E21: #N/A | F21: #N/A | G21: #N/A | H21: SECO | J21: 1 | K21: 1 | L21: CN12
A22: 1796 | B22: CILANTRO 120 G | C22: NEVERA F | D22: INACTIVO | E22: 10666.66 | F22: #DIV/0! | G22: 0 | H22: FRIO | K22: 1 | L22: CN10
A23: 2606 | B23: CIRUELA IMPORTADA 500 G | C23: NEVERA F | D23: INACTIVO | E23: #N/A | F23: #N/A | G23: #N/A | H23: FRIO | K23: 1 | L23: CN12
A24: 1797 | B24: CIRUELA NACIONAL 400 G | C24: NEVERA F | D24: ACTIVO | E24: 2600 | F24: 0.011725444 | G24: 221740 | H24: FRIO | K24: 1 | L24: CN06 | AV24: X | AW24: X | AX24: X
A25: 1071 | B25: COGOLLO 3 UNIDADES 300 G | C25: NEVERA F | D25: ACTIVO | E25: 192962.37 | F25: 0.30390646 | G25: 634940 | H25: FRIO | K25: 1 | L25: CN10 | AV25: X | AW25: X | AX25: X
A26: 1072 | B26: ESPINACA 150 G | C26: NEVERA F | D26: ACTIVO | E26: 23800 | F26: 0.035295339 | G26: 674310 | H26: FRIO | K26: 1 | L26: CN10 | AV26: X | AW26: X | AX26: X
A27: 1084 | B27: FRESA 250 G | C27: NEVERA F | D27: INACTIVO | E27: 4500 | F27: #DIV/0! | G27: 0 | H27: FRIO | J27: 1 | K27: 1 | L27: CN12
A28: 1800 | B28: GRANADILLA 450 G | C28: EXTENDIDO | D28: INACTIVO | E28: #N/A | F28: #N/A | G28: #N/A | H28: SECO | J28: 1 | K28: 1 | L28: CN08
A29: 1801 | B29: GUAYABA PERA 500 G | C29: EXTENDIDO | D29: INACTIVO | E29: #N/A | F29: #N/A | G29: #N/A | H29: SECO | J29: 1 | K29: 1 | L29: CN08
A30: 1820 | B30: GULUPA 500 G | C30: EXTENDIDO | D30: INACTIVO | E30: #N/A | F30: #N/A | G30: #N/A | H30: SECO | J30: 1 | K30: 1 | L30: CN10
A31: 2608 | B31: KIWI 300 G | C31: NEVERA F | D31: INACTIVO | E31: #N/A | F31: #N/A | G31: #N/A | H31: FRIO | K31: 1 | L31: CN12
A32: 1803 | B32: KIWI 200 G | C32: EXTENDIDO | D32: ACTIVO | E32: 100323.74 | F32: 0.077751054 | G32: 1290320 | H32: SECO | J32: 1 | K32: 1 | L32: CN08 | AQ32: X | AR32: X | AS32: X | AT32: X | AU32: X
A33: 1079 | B33: LECHUGA CRESPA VERDE UNIDAD | C33: NEVERA F | D33: ACTIVO | E33: 421282.2 | F33: 0.42111796 | G33: 1000390 | H33: FRIO | J33: 1 | K33: 1 | L33: CN12 | AV33: X | AW33: X | AX33: X
A34: 965 | B34: LIMON TAHITI 500 G | C34: BASICO | D34: ACTIVO | E34: 468136.21 | F34: 0.32631828 | G34: 1434600 | H34: SECO | I34: 1 | J34: 1 | K34: 1 | L34: CN12 | M34: X | N34: X | O34: X | P34: X | Q34: X | R34: X | S34: X | T34: X | U34: X | V34: X | W34: X | X34: X | Y34: X | Z34: X | AA34: X | AB34: X | AC34: X | AD34: X | AE34: X | AF34: X | AG34: X | AH34: X | AI34: X | AJ34: X | AK34: X | AL34: X | AM34: X | AN34: X | AO34: X | AP34: X | AQ34: X | AR34: X | AS34: X | AT34: X | AU34: X | AV34: X | AW34: X | AX34: X
A35: 2247 | B35: LIMON X 1000 G | C35: BASICO | D35: INACTIVO | E35: #N/A | F35: #N/A | G35: #N/A | H35: SECO | I35: 1 | J35: 1 | K35: 1 | L35: CN10
A36: 1804 | B36: LULO 600 G | C36: NEVERA F | D36: ACTIVO | E36: 93190.65 | F36: 0.30671971 | G36: 303830 | H36: FRIO | K36: 1 | L36: CN08 | AV36: X | AW36: X | AX36: X
A37: 1805 | B37: MANDARINA 500 G | C37: EXTENDIDO | D37: INACTIVO | E37: 2898 | F37: #DIV/0! | G37: 0 | H37: SECO | J37: 1 | K37: 1 | L37: CN08
A38: 2600 | B38: MANDARINA IMPORTADA *500GR | C38: NEVERA F | D38: INACTIVO | E38: #N/A | F38: #N/A | G38: #N/A | H38: FRIO | K38: 1 | L38: CN12
A39: 1807 | B39: MANGO VARIEDAD UNIDAD | C39: EXTENDIDO | D39: ACTIVO | E39: 342900.27 | F39: 0.37751458 | G39: 908310 | H39: SECO | J39: 1 | K39: 1 | L39: CN10 | AQ39: X | AR39: X | AS39: X | AT39: X | AU39: X
A40: 1671 | B40: MANZANA ROYAL GALA UND | C40: BASICO | D40: ACTIVO | E40: 1436150.3 | F40: 0.17945149 | G40: 8003000 | H40: SECO | I40: 1 | J40: 1 | K40: 1 | L40: CN25 | M40: X | N40: X | O40: X | P40: X | Q40: X | R40: X | S40: X | T40: X | U40: X | V40: X | W40: X | X40: X | Y40: X | Z40: X | AA40: X | AB40: X | AC40: X | AD40: X | AE40: X | AF40: X | AG40: X | AH40: X | AI40: X | AJ40: X | AK40: X | AL40: X | AM40: X | AN40: X | AO40: X | AP40: X | AQ40: X | AR40: X | AS40: X | AT40: X | AU40: X | AV40: X | AW40: X | AX40: X
...

Sheet Segmentación SUR - HUILA
L1: Tienda | M1: N06 | N1: N11 | O1: N15 | P1: N16 | Q1: N17 | R1: N21 | S1: N22 | T1: N24 | U1: N27 | V1: N29 | W1: N31 | X1: N34 | Y1: N35 | Z1: N37 | AA1: N39 | AB1: N41 | AC1: N01 | AD1: N10 | AE1: N18 | AF1: N20 | AG1: N33
L2: Nombre tienda | M2: CAMPO ALEGRE | N2: BELLA VISTA | O2: PITALITO 4 | P2: RIVERA | Q2: TERUEL | R2: PAEZ LA PLATA | S2: ISNOS | T2: GARZON4 | U2: TARQUI | V2: SALADOBLANCO | W2: PAICOL | X2: ALTAMIRA HUILA | Y2: BELEN DE LOS ANDAQUIES | Z2: QUIRINAL | AA2: PALERMO | AB2: TORRES DEL CAFE | AC2: PITALITO | AD2: BERDEZ | AE2: TELLO | AF2: YAGUARA | AG2: TESORO
L3: N S E | M3: 2 | N3: 2 | O3: 2 | P3: 2 | Q3: 3 | R3: 2 | S3: 2 | T3: 2 | U3: 2 | V3: 2 | W3: 2 | X3: 2 | Y3: 2 | Z3: 5 | AA3: 3 | AB3: 3 | AC3: 2 | AD3: 2 | AE3: 3 | AF3: 2 | AG3: 2
L4: NEVERA AUTOCONTENIDA | M4: NO | N4: NO | O4: NO | P4: NO | Q4: NO | R4: NO | S4: NO | T4: NO | U4: NO | V4: NO | W4: NO | X4: NO | Y4: NO | Z4: NO | AA4: NO | AB4: NO | AC4: NO | AD4: NO | AE4: NO | AF4: NO | AG4: NO
L5: CANTIDAD MUEBLES FRUVER | M5: 1 | N5: 3 | O5: 1 | P5: 2 | Q5: 1 | R5: 1 | S5: 2 | T5: 2 | U5: 2 | V5: 1 | W5: 1 | X5: 2 | Y5: 1 | Z5: 1 | AA5: 1 | AB5: 2 | AC5: 2 | AD5: 1 | AE5: 1 | AF5: 1 | AG5: 1
L6: VTA PROM FRUVER | M6: 48301.667 | N6: 106380 | O6: 38636 | P6: 116120.33 | Q6: 120238.67 | R6: 75298.333 | S6: 57127 | T6: 63760.333 | U6: 104822 | V6: 98708.333 | W6: 74513 | X6: 81491 | Y6: 101737 | Z6: 119923.67 | AA6: 81859.333 | AB6: 98185.667 | AC6: 148413.33 | AD6: 227813.33 | AE6: 145931 | AF6: 145535.67 | AG6: 235811
L7: % PARTICIP | M7: 0.009 | N7: 0.012 | O7: 0.011 | P7: 0.012 | Q7: 0.013 | R7: 0.01 | S7: 0.012 | T7: 0.01 | U7: 0.013 | V7: 0.012 | W7: 0.014 | X7: 0.016 | Y7: 0.016 | Z7: 0.02 | AA7: 0.014 | AB7: 0.017 | AC7: 0.016 | AD7: 0.024 | AE7: 0.019 | AF7: 0.017 | AG7: 0.03
L8: TIPO DE PORTAFOLIO | M8: BÁSICO | N8: BÁSICO | O8: BÁSICO | P8: BÁSICO | Q8: BÁSICO | R8: BÁSICO | S8: BÁSICO | T8: BÁSICO | U8: BÁSICO | V8: BÁSICO | W8: BÁSICO | X8: BÁSICO | Y8: BÁSICO | Z8: BÁSICO | AA8: BÁSICO | AB8: BÁSICO | AC8: BÁSICO + EXTENDIDO | AD8: BÁSICO + EXTENDIDO | AE8: BÁSICO + EXTENDIDO | AF8: BÁSICO + EXTENDIDO | AG8: BÁSICO + EXTENDIDO
A9: ITEM | B9: DESCRIPCION | C9: CLUSTERIZACIÓN | D9: ESTADO | E9: Merma 01 A 30 JUNIO $ | F9: % merma JUNIO | G9: venta JUNIO $ | H9: EXHIBICION | I9: CARAS BSC | J9: CARAS BSC+EXT | K9: CARAS BSC+EXT+NEV | L9: U.M. | M9: 17 | N9: 17 | O9: 17 | P9: 17 | Q9: 17 | R9: 17 | S9: 17 | T9: 17 | U9: 17 | V9: 17 | W9: 17 | X9: 17 | Y9: 17 | Z9: 17 | AA9: 17 | AB9: 17 | AC9: 28 | AD9: 28 | AE9: 28 | AF9: 28 | AG9: 28
A10: 1561 | B10: AGUACATE HASS UND | C10: BASICO | D10: ACTIVO | E10: =VLOOKUP(A10,'tabla datos'!$H$160:$K$206,4,0) -> 972543.57 | F10: =E10/G10 -> 0.1910597 | G10: =VLOOKUP(A10,'tabla datos'!$H$160:$K$206,3,0) -> 5090260 | H10: SECO | I10: 1 | J10: 1 | K10: 1 | L10: CN36 | M10: X | N10: X | O10: X | P10: X | Q10: X | R10: X | S10: X | T10: X | U10: X | V10: X | W10: X | X10: X | Y10: X | Z10: X | AA10: X | AB10: X | AC10: X | AD10: X | AE10: X | AF10: X | AG10: X
A11: 1074 | B11: AGUACATE VARIEDAD 400 G | C11: EXTENDIDO | D11: ACTIVO | E11: =VLOOKUP(A11,'tabla datos'!$H$160:$K$206,4,0) -> 96766.63 | F11: =E11/G11 -> 0.068565113 | G11: =VLOOKUP(A11,'tabla datos'!$H$160:$K$206,3,0) -> 1411310 | H11: SECO | J11: 1 | K11: 1 | L11: CN10 | AC11: X | AD11: X | AE11: X | AF11: X | AG11: X
A12: 1819 | B12: AHUYAMA ZAKATA 600 G | C12: EXTENDIDO | D12: ACTIVO | E12: =VLOOKUP(A12,'tabla datos'!$H$160:$K$206,4,0) -> 57654.9 | F12: =E12/G12 -> 0.29896241 | G12: =VLOOKUP(A12,'tabla datos'!$H$160:$K$206,3,0) -> 192850 | H12: SECO | K12: 1 | L12: CN10 | AC12: X | AD12: X | AE12: X | AF12: X | AG12: X
A13: 155 | B13: AJO 3 UND | C13: BASICO | D13: ACTIVO | E13: =VLOOKUP(A13,'tabla datos'!$H$160:$K$206,4,0) -> 65838.89 | F13: =E13/G13 -> 0.027962884 | G13: =VLOOKUP(A13,'tabla datos'!$H$160:$K$206,3,0) -> 2354510 | H13: SECO | I13: 1 | J13: 1 | K13: 1 | L13: CN50 | M13: X | N13: X | O13: X | P13: X | Q13: X | R13: X | S13: X | T13: X | U13: X | V13: X | W13: X | X13: X | Y13: X | Z13: X | AA13: X | AB13: X | AC13: X | AD13: X | AE13: X | AF13: X | AG13: X
A14: 1793 | B14: APIO 300 G | C14: NEVERA F | D14: INACTIVO | E14: =VLOOKUP(A14,'tabla datos'!$H$160:$K$206,4,0) -> #N/A | F14: =E14/G14 -> #N/A | G14: =VLOOKUP(A14,'tabla datos'!$H$160:$K$206,3,0) -> #N/A | H14: FRIO | K14: 1 | L14: CN08
A15: 157 | B15: ARANDANOS FRESCOS 125 G | C15: BASICO | D15: ACTIVO | E15: =VLOOKUP(A15,'tabla datos'!$H$160:$K$206,4,0) -> 568369.1 | F15: =E15/G15 -> 0.082084562 | G15: =VLOOKUP(A15,'tabla datos'!$H$160:$K$206,3,0) -> 6924190 | H15: FRIO | I15: 1 | J15: 1 | K15: 1 | L15: CN12 | M15: X | N15: X | O15: X | P15: X | Q15: X | R15: X | S15: X | T15: X | U15: X | V15: X | W15: X | X15: X | Y15: X | Z15: X | AA15: X | AB15: X | AC15: X | AD15: X | AE15: X | AF15: X | AG15: X
A16: 1210 | B16: BANANO UNIDAD | C16: BASICO | D16: ACTIVO | E16: =VLOOKUP(A16,'tabla datos'!$H$160:$K$206,4,0) -> 1010425.1 | F16: =E16/G16 -> 0.20863834 | G16: =VLOOKUP(A16,'tabla datos'!$H$160:$K$206,3,0) -> 4842950 | H16: SECO | I16: 1 | J16: 1 | K16: 1 | L16: C100 | M16: X | N16: X | O16: X | P16: X | Q16: X | R16: X | S16: X | T16: X | U16: X | V16: X | W16: X | X16: X | Y16: X | Z16: X | AA16: X | AB16: X | AC16: X | AD16: X | AE16: X | AF16: X | AG16: X
A17: 1795 | B17: BROCOLI 250 G | C17: NEVERA F | D17: INACTIVO | E17: =VLOOKUP(A17,'tabla datos'!$H$160:$K$206,4,0) -> #N/A | F17: =E17/G17 -> #N/A | G17: =VLOOKUP(A17,'tabla datos'!$H$160:$K$206,3,0) -> #N/A | H17: FRIO | K17: 1 | L17: CN06
A18: 2472 | B18: CEBOLLA BLANCA SEMIPELADA CABEZONA 1000 G | C18: BASICO | D18: INACTIVO | E18: =VLOOKUP(A18,'tabla datos'!$H$160:$K$206,4,0) -> #N/A | F18: =E18/G18 -> #N/A | G18: =VLOOKUP(A18,'tabla datos'!$H$160:$K$206,3,0) -> #N/A | H18: SECO | I18: 1 | J18: 1 | K18: 1 | L18: CN10
A19: 175 | B19: CEBOLLA BLANCA CABEZONA 500 G | C19: BASICO | D19: ACTIVO | E19: =VLOOKUP(A19,'tabla datos'!$H$160:$K$206,4,0) -> 68854.9 | F19: =E19/G19 -> 0.047797647 | G19: =VLOOKUP(A19,'tabla datos'!$H$160:$K$206,3,0) -> 1440550 | H19: SECO | I19: 1 | J19: 1 | K19: 1 | L19: CN12 | M19: X | N19: X | O19: X | P19: X | Q19: X | R19: X | S19: X | T19: X | U19: X | V19: X | W19: X | X19: X | Y19: X | Z19: X | AA19: X | AB19: X | AC19: X | AD19: X | AE19: X | AF19: X | AG19: X
A20: 2052 | B20: CEBOLLA LARGA 500G | C20: EXTENDIDO | D20: ACTIVO | E20: =VLOOKUP(A20,'tabla datos'!$H$160:$K$206,4,0) -> 65992.81 | F20: =E20/G20 -> 0.38062527 | G20: =VLOOKUP(A20,'tabla datos'!$H$160:$K$206,3,0) -> 173380 | H20: FRIO | J20: 1 | K20: 1 | L20: CN10 | AC20: X | AD20: X | AE20: X | AF20: X | AG20: X
A21: 754 | B21: CEBOLLA ROJA 500 G | C21: EXTENDIDO | D21: INACTIVO | E21: =VLOOKUP(A21,'tabla datos'!$H$160:$K$206,4,0) -> #N/A | F21: =E21/G21 -> #N/A | G21: =VLOOKUP(A21,'tabla datos'!$H$160:$K$206,3,0) -> #N/A | H21: SECO | J21: 1 | K21: 1 | L21: CN12
A22: 1796 | B22: CILANTRO 120 G | C22: NEVERA F | D22: INACTIVO | E22: =VLOOKUP(A22,'tabla datos'!$H$160:$K$206,4,0) -> #N/A | F22: =E22/G22 -> #N/A | G22: =VLOOKUP(A22,'tabla datos'!$H$160:$K$206,3,0) -> #N/A | H22: FRIO | K22: 1 | L22: CN10
A23: 2606 | B23: CIRUELA IMPORTADA 500 G | C23: NEVERA F | D23: INACTIVO | E23: =VLOOKUP(A23,'tabla datos'!$H$160:$K$206,4,0) -> #N/A | F23: =E23/G23 -> #N/A | G23: =VLOOKUP(A23,'tabla datos'!$H$160:$K$206,3,0) -> #N/A | H23: FRIO | K23: 1 | L23: CN12
A24: 1797 | B24: CIRUELA NACIONAL 400 G | C24: NEVERA F | D24: INACTIVO | E24: =VLOOKUP(A24,'tabla datos'!$H$160:$K$206,4,0) -> #N/A | F24: =E24/G24 -> #N/A | G24: =VLOOKUP(A24,'tabla datos'!$H$160:$K$206,3,0) -> #N/A | H24: FRIO | K24: 1 | L24: CN06
A25: 1071 | B25: COGOLLO 3 UNIDADES 300 G | C25: NEVERA F | D25: INACTIVO | E25: =VLOOKUP(A25,'tabla datos'!$H$160:$K$206,4,0) -> #N/A | F25: =E25/G25 -> #N/A | G25: =VLOOKUP(A25,'tabla datos'!$H$160:$K$206,3,0) -> #N/A | H25: FRIO | K25: 1 | L25: CN10
A26: 1072 | B26: ESPINACA 150 G | C26: NEVERA F | D26: INACTIVO | E26: =VLOOKUP(A26,'tabla datos'!$H$160:$K$206,4,0) -> #N/A | F26: =E26/G26 -> #N/A | G26: =VLOOKUP(A26,'tabla datos'!$H$160:$K$206,3,0) -> #N/A | H26: FRIO | K26: 1 | L26: CN10
A27: 1084 | B27: FRESA 250 G | C27: NEVERA F | D27: INACTIVO | E27: =VLOOKUP(A27,'tabla datos'!$H$160:$K$206,4,0) -> #N/A | F27: =E27/G27 -> #N/A | G27: =VLOOKUP(A27,'tabla datos'!$H$160:$K$206,3,0) -> #N/A | H27: FRIO | J27: 1 | K27: 1 | L27: CN12
A28: 1800 | B28: GRANADILLA 450 G | C28: EXTENDIDO | D28: INACTIVO | E28: =VLOOKUP(A28,'tabla datos'!$H$160:$K$206,4,0) -> 33500 | F28: =E28/G28 -> 0.088751126 | G28: =VLOOKUP(A28,'tabla datos'!$H$160:$K$206,3,0) -> 377460 | H28: SECO | J28: 1 | K28: 1 | L28: CN08
A29: 1801 | B29: GUAYABA PERA 500 G | C29: EXTENDIDO | D29: INACTIVO | E29: =VLOOKUP(A29,'tabla datos'!$H$160:$K$206,4,0) -> #N/A | F29: =E29/G29 -> #N/A | G29: =VLOOKUP(A29,'tabla datos'!$H$160:$K$206,3,0) -> #N/A | H29: SECO | J29: 1 | K29: 1 | L29: CN08
A30: 1820 | B30: GULUPA 500 G | C30: EXTENDIDO | D30: INACTIVO | E30: =VLOOKUP(A30,'tabla datos'!$H$160:$K$206,4,0) -> #N/A | F30: =E30/G30 -> #N/A | G30: =VLOOKUP(A30,'tabla datos'!$H$160:$K$206,3,0) -> #N/A | H30: SECO | J30: 1 | K30: 1 | L30: CN10
A31: 2608 | B31: KIWI 300 G | C31: NEVERA F | D31: INACTIVO | E31: =VLOOKUP(A31,'tabla datos'!$H$160:$K$206,4,0) -> #N/A | F31: =E31/G31 -> #N/A | G31: =VLOOKUP(A31,'tabla datos'!$H$160:$K$206,3,0) -> #N/A | H31: FRIO | K31: 1 | L31: CN12
A32: 1803 | B32: KIWI 200 G | C32: EXTENDIDO | D32: ACTIVO | E32: =VLOOKUP(A32,'tabla datos'!$H$160:$K$206,4,0) -> 22925.45 | F32: =E32/G32 -> 0.028804435 | G32: =VLOOKUP(A32,'tabla datos'!$H$160:$K$206,3,0) -> 795900 | H32: SECO | J32: 1 | K32: 1 | L32: CN08 | AC32: X | AD32: X | AE32: X | AF32: X | AG32: X
A33: 1079 | B33: LECHUGA CRESPA VERDE UNIDAD | C33: NEVERA F | D33: INACTIVO | E33: =VLOOKUP(A33,'tabla datos'!$H$160:$K$206,4,0) -> #N/A | F33: =E33/G33 -> #N/A | G33: =VLOOKUP(A33,'tabla datos'!$H$160:$K$206,3,0) -> #N/A | H33: FRIO | J33: 1 | K33: 1 | L33: CN12
A34: 965 | B34: LIMON TAHITI 500 G | C34: BASICO | D34: ACTIVO | E34: =VLOOKUP(A34,'tabla datos'!$H$160:$K$206,4,0) -> 291280.13 | F34: =E34/G34 -> 0.31402496 | G34: =VLOOKUP(A34,'tabla datos'!$H$160:$K$206,3,0) -> 927570 | H34: SECO | I34: 1 | J34: 1 | K34: 1 | L34: CN12 | M34: X | N34: X | O34: X | P34: X | Q34: X | R34: X | S34: X | T34: X | U34: X | V34: X | W34: X | X34: X | Y34: X | Z34: X | AA34: X | AB34: X | AC34: X | AD34: X | AE34: X | AF34: X | AG34: X
A35: 2247 | B35: LIMON X 1000 G | C35: BASICO | D35: INACTIVO | E35: =VLOOKUP(A35,'tabla datos'!$H$160:$K$206,4,0) -> #N/A | F35: =E35/G35 -> #N/A | G35: =VLOOKUP(A35,'tabla datos'!$H$160:$K$206,3,0) -> #N/A | H35: SECO | I35: 1 | J35: 1 | K35: 1 | L35: CN10
A36: 1804 | B36: LULO 600 G | C36: NEVERA F | D36: INACTIVO | E36: =VLOOKUP(A36,'tabla datos'!$H$160:$K$206,4,0) -> 33560.68 | F36: =E36/G36 -> 6.7255872 | G36: =VLOOKUP(A36,'tabla datos'!$H$160:$K$206,3,0) -> 4990 | H36: FRIO | K36: 1 | L36: CN08
A37: 1805 | B37: MANDARINA 500 G | C37: EXTENDIDO | D37: INACTIVO | E37: =VLOOKUP(A37,'tabla datos'!$H$160:$K$206,4,0) -> #N/A | F37: =E37/G37 -> #N/A | G37: =VLOOKUP(A37,'tabla datos'!$H$160:$K$206,3,0) -> #N/A | H37: SECO | J37: 1 | K37: 1 | L37: CN08
A38: 2600 | B38: MANDARINA IMPORTADA *500GR | C38: NEVERA F | D38: INACTIVO | E38: =VLOOKUP(A38,'tabla datos'!$H$160:$K$206,4,0) -> #N/A | F38: =E38/G38 -> #N/A | G38: =VLOOKUP(A38,'tabla datos'!$H$160:$K$206,3,0) -> #N/A | H38: FRIO | K38: 1 | L38: CN12
A39: 1807 | B39: MANGO VARIEDAD UNIDAD | C39: EXTENDIDO | D39: ACTIVO | E39: =VLOOKUP(A39,'tabla datos'!$H$160:$K$206,4,0) -> 69591.51 | F39: =E39/G39 -> 0.066857699 | G39: =VLOOKUP(A39,'tabla datos'!$H$160:$K$206,3,0) -> 1040890 | H39: SECO | J39: 1 | K39: 1 | L39: CN10 | AC39: X | AD39: X | AE39: X | AF39: X | AG39: X
A40: 1671 | B40: MANZANA ROYAL GALA UND | C40: BASICO | D40: ACTIVO | E40: =VLOOKUP(A40,'tabla datos'!$H$160:$K$206,4,0) -> 401219.16 | F40: =E40/G40 -> 0.080142052 | G40: =VLOOKUP(A40,'tabla datos'!$H$160:$K$206,3,0) -> 5006350 | H40: SECO | I40: 1 | J40: 1 | K40: 1 | L40: CN25 | M40: X | N40: X | O40: X | P40: X | Q40: X | R40: X | S40: X | T40: X | U40: X | V40: X | W40: X | X40: X | Y40: X | Z40: X | AA40: X | AB40: X | AC40: X | AD40: X | AE40: X | AF40: X | AG40: X
...

Sheet Hoja 8
A3: Region | B3: Tienda | C3: Nombre tienda | D3: N S E | E3: NEVERA AUTOCONTENIDA | F3: CANTIDAD MUEBLES FRUVER | G3: TIPO DE PORTAFOLIO
A4: Tolima | B4: S01 | C4: GIRARDOT PANCHES | D4: 3 | E4: NO | F4: 2 | G4: B
A5: Tolima | B5: T05 | C5: MELGAR | D5: 2 | E5: NO | F5: 2 | G5: B
A6: Tolima | B6: T06 | C6: HONDA OBRERO | D6: 2 | E6: NO | F6: 2 | G6: B
A7: Tolima | B7: T07 | C7: SALADO 1 | D7: 2 | E7: NO | F7: 2 | G7: B
A8: Tolima | B8: T09 | C8: CAJAMARCA | D8: 2 | E8: NO | F8: 2 | G8: B
A9: Tolima | B9: T11 | C9: LIBANO 1 | D9: 3 | E9: NO | F9: 2 | G9: B
A10: Tolima | B10: T13 | C10: FLANDES TOLIMA | D10: 2 | E10: NO | F10: 2 | G10: B
A11: Tolima | B11: T16 | C11: ORTEGA | D11: 2 | E11: NO | F11: 2 | G11: B
A12: Tolima | B12: T17 | C12: CHAPARRAL | D12: 2 | E12: NO | F12: 2 | G12: B
A13: Tolima | B13: T19 | C13: MARIQUITA 1 | D13: 2 | E13: NO | F13: 2 | G13: B
A14: Tolima | B14: T21 | C14: CARMEN DE APICALA | D14: 2 | E14: NO | F14: 2 | G14: B
A15: Tolima | B15: T23 | C15: CHAPARRAL 2 | D15: 2 | E15: NO | F15: 1 | G15: B
... A62: Huila | B62: N33 | C62: TESORO | D62: 2 | E62: NO | F62: 1 | G62: BÁSICO + EXTENDIDO

Sheet Tabla dinámica 3
